Workbook

Sheet МАКЕТ
E8: Распределение энергоресурсов по виду: | H8: электроэнергия продажа | I8: за июнь 2026
H9: (наименование услуги) | I9: (дата)
B11: ЭЛ.ПОЧТА | C11: телефон | D11: контактное лицо | E11: № п/п | F11: Договор | G11: ИНН | H11: Контрагент | I11: Потребление ЭЭ, МВтч | J11: Стоимость ЭЭ, руб./МВтч | K11: руб. с НДС | L11: с авансами
B12: rch@electrotherm.ru | C12: 8(926)586-10-31; 8(812)309-71-27 доб. 116 | D12: Чуйко Роман Станиславович | E12: =ROW()-11 -> 1 | F12: 92100-542ЭА от 01.08.2021 | G12: 7838493420 | H12: АЛЬФАКОМ ООО | I12: =[1]Итог!D42 -> 14.255 | J12: =[1]Ведомость!D49 -> 10470 | K12: =I12*J12*1.22 -> 182084.82 | O12: 14.255
A13: п | B13: zhenyahor@mail.ru | C13: 8-951-684-3185; 8-911-701-71-31 | D13: Евгений Александрович директор | E13: =ROW()-11 -> 2 | F13: 92100-294Э от 01.02.2017 | G13: 7805643007 | H13: АДАМ ООО | I13: =[1]Итог!D36 -> 2.602 | J13: =[1]Ведомость!D43 -> 10470 | K13: =I13*J13*1.22 -> 33236.387 | O13: 6
A14: п | B14: akomplius@bk.ru | C14: 962-702-58-50 | E14: =ROW()-11 -> 3 | F14: 92100-387Э от 01.01.2018 | G14: 7805720090 | H14: АКОМ + ООО | I14: =[1]Итог!D37 -> 6 | J14: =[1]Ведомость!D44 -> 10470 | K14: =I14*J14*1.22 -> 76640.4 | O14: 0.156
B15: ipsmebelion@yandex.ru | C15: 8-921-375-35-45 | D15: Вячеслав Степанович | E15: =ROW()-11 -> 4 | F15: 92100-674ЭА от 01.04.2024 | G15: 7807276715 | H15: ВашДиВАН ООО | I15: =[1]Итог!D39 -> 0.156 | J15: =[1]Ведомость!D46 -> 10470 | K15: =I15*J15*1.22 -> 1992.6504 | O15: 2.779
A16: п | B16: VOcheretyany@alfabank.ru | C16: 8-921-778-20-97 | D16: комендант Очеретяный Виктор | E16: =ROW()-11 -> 5 | F16: 92100-166Э от 01.03.2015 | G16: 7728168971 | H16: АЛЬФА-БАНК АО | I16: =[1]Итог!D40 -> 2.779 | J16: =[1]Ведомость!D47 -> 10470 | K16: =I16*J16*1.22 -> 35497.279 | O16: 3.033
A17: п | B17: elena.k@rugidro.com; korniloww@rambler.ru | C17: 8-905-235-24-44 | D17: Корнилова Елена Леонидовна | E17: =ROW()-11 -> 6 | F17: 92100-369Э от 01.10.2017 | G17: 7805045896 | H17: АЛЬФАГИДРАВЛИКА ООО | I17: =[1]Итог!D41 -> 3.033 | J17: =[1]Ведомость!D48 -> 10470 | K17: =I17*J17*1.22 -> 38741.722 | O17: 3.1
A18: п | B18: y.sapunkov@krupa-national.ru | C18: 8-921-403-26-43 | E18: =ROW()-11 -> 7 | F18: 92100-053Э от 01.01.2009г. | G18: 7816108153 | H18: АНГСТРЕМ | I18: =[1]Итог!D43 -> 4.074 | J18: =[1]Ведомость!D50 -> 10470 | K18: =I18*J18*1.22 -> 52038.832 | O18: 43.609
B19: Juriy.Borisov@sptz.kzgroup.ru; Stecuk@sptz.kzgroup.ru; Dmitriy.Stripuhovskiy@sptz.kzgroup.ru | E19: =ROW()-11 -> 8 | F19: 92100-319ЭС от 01.06.2024 | G19: 7805059867 | H19: АО Петербургский тракторный завод | I19: =[1]Итог!C14 -> 0 | J19: =[1]Ведомость!D22 -> 8940 | K19: =I19*J19*1.22 -> 0 | O19: 9.667
A20: п | B20: dsch50@mail.ru | C20: 8-911-212-68-40 | E20: =ROW()-11 -> 9 | F20: 92100-092Э от 01.01.2009г. | G20: 7805451231 | H20: АПРИ ООО | I20: =[1]Итог!D44 -> 12.42 | J20: =[1]Ведомость!D51 -> 10470 | K20: =I20*J20*1.22 -> 158645.63 | O20: 66.68
B21: storage.spb@a-priory.ru | C21: 8-921-337-64-73 | E21: =ROW()-11 -> 10 | F21: 92100-524Э от 01.09.2020 | G21: 9721068026 | H21: А-ПРИОРИ ООО | I21: =[1]Итог!D34 -> 16.635 | J21: =[1]Ведомость!D42 -> 10470 | K21: =I21*J21*1.22 -> 212485.51 | O21: 0.322
A22: п | B22: dk@astrinmet.ru | C22: 8-911-037-37-06 | D22: Наталия Сергеевна Норина бух. | E22: =ROW()-11 -> 11 | F22: 92100-421Э от 16.07.2018 | G22: 7813248321 | H22: АСТРИНМЕТ ООО | I22: =[1]Итог!D45 -> 3.1 | J22: =[1]Ведомость!D52 -> 10470 | K22: =I22*J22*1.22 -> 39597.54 | O22: 0.103
A23: п | B23: bmiz-gladilin@yandex.ru | C23: 942-86-14, 329-02-54 | D23: Гладилин Юрий Леонидович | E23: =ROW()-11 -> 12 | F23: 92100-327Э от 01.04.2017 | G23: 7805438872 | H23: БАЛТ.МИП ООО | I23: =[1]Итог!D48 -> 43.609 | J23: =[1]Ведомость!D54 -> 10470 | K23: =I23*J23*1.22 -> 557035.2 | O23: 24.077
B24: tatyana.N.lobas@bspb.ru; | C24: 988123295050, 988123295082 | E24: =ROW()-11 -> 13 | F24: 92100-145Э от 01.12.2013 | G24: 7831000027 | H24: ПАО Банк "Санкт-Петербург" | I24: =[1]Итог!D49 -> 9.667 | J24: =[1]Ведомость!D55 -> 10470 | K24: =I24*J24*1.22 -> 123480.46 | O24: 4.914
A25: п | B25: bks1607@yandex.ru; bogvera@yandex.ru | C25: 8-921-429-13-85 | D25: Сергей Белынский | E25: =ROW()-11 -> 14 | F25: 92100-657ЭА от 01.10.2023 | G25: 781407520703 | H25: Белынский С.В. | I25: =[1]Итог!D51 -> 87.129 | J25: =[1]Ведомость!D58 -> 10470 | K25: =I25*J25*1.22 -> 1112933.6 | O25: 11.1
A26: п | B26: alex-stepanov86@mail.ru; bcsheremetev47@mail.ru | C26: 8-911-826-90-82 | D26: Александр Степанов | E26: =ROW()-11 -> 15 | F26: 92100-100Э от 01.05.2009г | G26: 7805442068 | H26: БИЗНЕС ЦЕНТР ШЕРЕМЕТЕВ ООО | I26: =[1]Итог!D8 -> 66.68 | J26: =[1]Ведомость!D15 -> 8940 | K26: =I26*J26*1.22 -> 727265.42 | O26: 109.2
B27: Bmk.trubogib@mail.ru | C27: 331-08-40; 331 39 70 | E27: =ROW()-11 -> 16 | F27: 92100-033Э от 01.01.2009г. | G27: 7805176673 | H27: БМК | I27: =[1]Итог!D52 -> 0.322 | J27: =[1]Ведомость!D59 -> 10470 | K27: =I27*J27*1.22 -> 4113.0348 | O27: 1.184
A28: п | B28: shop7@svmspb.ru; svm@svmspb.ru | C28: 8-911-285-35-98 | E28: =ROW()-11 -> 17 | F28: 92100-419Э от 01.06.2018 | G28: 781135852869 | H28: Бруданин Владимир Валериевич | I28: =[1]Итог!D53 -> 0.103 | J28: =[1]Ведомость!D60 -> 10470 | K28: =I28*J28*1.22 -> 1315.6602 | O28: 1.46
A29: п | B29: vektormex@mail.ru | C29: 928-82-02 | D29: Сергей Александрович | E29: =ROW()-11 -> 18 | F29: 92100-306Э от 01.02.2017 | G29: 7804569463 | H29: ВЕКТОРМЕХ ООО | I29: =[1]Итог!D54 -> 0.975 | J29: =[1]Ведомость!D62 -> 10470 | K29: =I29*J29*1.22 -> 12454.065 | O29: 210.453
A30: п | B30: info@west-ter.com | C30: 8-921-963-95-23 | E30: =ROW()-11 -> 19 | F30: 92100-549ЭА от 01.03.2021 | G30: 7805774867 | H30: ВЕСТЕР ООО | I30: =[1]Итог!D55 -> 0.065 | J30: =[1]Ведомость!D63 -> 10470 | K30: =I30*J30*1.22 -> 830.271 | O30: 0.4
B31: s.zhuravlev@visotec.ru; ez@evroznak.spb.ru | C31: 8-981-973-04-20 | D31: Журавлев Сергей | E31: =ROW()-11 -> 20 | F31: 92100-108Э от 01.01.2009г. | G31: 7805665201 | H31: ВИЗОТЕК РУС ООО | I31: =[1]Итог!D56 -> 78.935 | J31: =[1]Ведомость!D64 -> 10470 | K31: =I31*J31*1.22 -> 1008268.3 | O31: 2.579
A32: п | B32: vma1999@mail.ru; baltlog@rambler.ru | C32: 921-960-31-24 | D32: Максим Аркадьевич | E32: =ROW()-11 -> 21 | F32: 92100-393Э от 29.01.2018 | G32: 781708945876 | H32: Возный Максим Аркадьевич | I32: =[1]Итог!D58 -> 16.86 | J32: =[1]Ведомость!D66 -> 10470 | K32: =I32*J32*1.22 -> 215359.52 | O32: 6.072
B33: kp@meteck.ru; info@meteck.ru | C33: 8-921-588-33-09 | D33: Овчинников Николай Александрович | E33: =ROW()-11 -> 22 | F33: 92100-594ЭА от 01.03.2022 | G33: 7801402258 | H33: МЕТЕК-ИНЖИНИРИНГ | I33: =[1]Итог!D106 -> 24.077 | J33: =[1]Ведомость!D114 -> 10470 | K33: =I33*J33*1.22 -> 307545.15 | O33: 685.648
A34: п | B34: elizaveta.lisina@gdr-s.ru | C34: 8-968-194-28-03 | D34: Лисина Елизавета | E34: =ROW()-11 -> 23 | F34: 92100-543Э от 01.02.2021 | G34: 7805772450 | H34: ГИДРАВЛИКСЕРВИС ООО | I34: =[1]Итог!D62 -> 4.914 | J34: =[1]Ведомость!D114 -> 10470 | K34: =I34*J34*1.22 -> 62768.488 | O34: 0.242
A35: п | B35: kistanovda@glassburg.com; info@glassburg.com | C35: 79214035203 | D35: директор Антон Валерьевич все решает | E35: =ROW()-11 -> 24 | F35: 92100-255Э от 22.09.2016 | G35: 7805312140 | H35: ГЛАССБУРГ ООО | I35: =[1]Итог!D63 -> 11.1 | J35: =[1]Ведомость!D70 -> 10470 | K35: =I35*J35*1.22 -> 141784.74 | O35: 62.171
A36: п | B36: aleksandr.shirokov@ilimgroup.ru | C36: 8-921-940-88-78 | D36: Александр Широков | E36: =ROW()-11 -> 25 | F36: 92100-203Э от 01.12.2015 | G36: 7840346335 | H36: Группа "Илим" | I36: =[1]Итог!D64 -> 109.2 | J36: =[1]Ведомость!D71 -> 10470 | K36: =I36*J36*1.22 -> 1394855.3 | O36: 0.66
A37: п | B37: 89110948101@mail.ru | C37: 8-911-094-81-01 | D37: Екатерина Мешалкова | E37: =ROW()-11 -> 26 | F37: 92100-416Э от 01.05.2018 | G37: 7841485187 | H37: ГСК ЭКС ООО | I37: =[1]Итог!D65 -> 1.184 | J37: =[1]Ведомость!D72 -> 10470 | K37: =I37*J37*1.22 -> 15123.706 | O37: 7.445
A38: п | B38: chvg@diateh.ru; office@diateh.ru | C38: 719-68-68 | E38: =ROW()-11 -> 27 | F38: 92100-449Э от 26.12.2018 | G38: 7825503030 | H38: ДИАЛОГ-ТЕХНИКА ООО | I38: =[1]Итог!D66 -> 1.46 | J38: =[1]Ведомость!D73 -> 10470 | K38: =I38*J38*1.22 -> 18649.164 | O38: 18
A39: п | B39: dizelinstr@mail.ru; a_lebedeva84@mail.ru | C39: 962-680-15-05 | E39: =ROW()-11 -> 28 | F39: 92100-448Э от 01.01.2019 | G39: 7842124465 | H39: ДИЗЕЛЬ-ИНСТРУМЕНТ СПБ ООО | I39: =[1]Итог!D67 -> 210.453 | J39: =[1]Ведомость!D74 -> 10470 | K39: =I39*J39*1.22 -> 2688200.4 | O39: 225.99
A40: п | B40: donata938@yandex.ru | C40: 8-921-885-43-59 | E40: =ROW()-11 -> 29 | F40: 92100-339Э от 08.07.2017 | G40: 780709242916 | H40: Дмитриенко | I40: =[1]Итог!D68 -> 0.4 | J40: =[1]Ведомость!D75 -> 10470 | K40: =I40*J40*1.22 -> 5109.36 | O40: 124.467
B41: dop0-metal@yandex.ru; baltstar@inbox.ru | C41: 989219055882 | E41: =ROW()-11 -> 30 | F41: 92100-253Э от 08.09.2016 | G41: 4703137366 | H41: ДОПУСК-0 ООО | I41: =[1]Итог!D69 -> 2.579 | J41: =[1]Ведомость!D76 -> 10470 | K41: =I41*J41*1.22 -> 32942.599 | O41: 385.01
A42: п | B42: evrovik2020@yandex.ru | C42: 326-55-95 | E42: =ROW()-11 -> 31 | F42: 92100-356Э от 01.08.2017 | G42: 7816647557 | H42: ЕВРОВИК МАШСЕРВИС ООО | I42: =[1]Итог!D71 -> 6.072 | J42: =[1]Ведомость!D78 -> 10470 | K42: =I42*J42*1.22 -> 77560.085 | O42: 1.098
A43: п | B43: 3307573@gmail.com; olga_a2008@mail.ru | C43: 7-965-057-78-00 Артур | E43: =ROW()-11 -> 32 | F43: 92100-535Э от 11.11.2020 | G43: 783900324772 | H43: Оникс ООО | I43: =[1]Итог!D72 -> 3 | J43: =[1]Ведомость!D79 -> 10470 | K43: =I43*J43*1.22 -> 38320.2 | O43: 3.564
B44: brygin.sv@k-energomash.ru | C44: +7 (911)984-96-29 | E44: =ROW()-11 -> 33 | F44: 92100-010Э/3-803-189-09-103 от 01.01.2009 | G44: 7805060301 | H44: ЗАВОД КИРОВ-ЭНЕРГОМАШ АО | I44: =[1]Итог!D23 -> 685.648 | J44: =[1]Ведомость!I289*1000 -> 8460 | K44: =I44*J44*1.22 -> 7076710.1 | O44: 22.712
A45: п | B45: i_zavyalov@inbox.ru; timofeev_dim@inbox.ru | C45: 8-962-700-14-65; 89110952014 по показаниям | D45: Завьялов Дмитрий Алексеевич | E45: =ROW()-11 -> 34 | F45: 92100-478Э от 01.11.2019 | G45: 7816583800 | H45: ЗАВЬЯЛОВ ООО | I45: =[1]Итог!D75 -> 2.333 | J45: =[1]Ведомость!D82 -> 10470 | K45: =I45*J45*1.22 -> 29800.342 | O45: 0.321
A46: п | B46: vasiyzoviylov@inbox.ru | C46: 8-921-940-66-51 | E46: =ROW()-11 -> 35 | F46: 92100-562ЭА от 01.04.2021 | G46: 591304618360 | H46: Завьялова Светлана Николаевна | I46: =[1]Итог!D76 -> 0.242 | J46: =[1]Ведомость!D83 -> 10470 | K46: =I46*J46*1.22 -> 3091.1628 | O46: 2.233
A47: п | B47: ecomarin2014@gmail.com; info@ivolga.in | C47: 8-921-184-90-80 | E47: =ROW()-11 -> 36 | F47: 92100-139Э от 01.10.2013г. | G47: 7805468411 | H47: ИВОЛГА ООО | I47: =[1]Итог!D77 -> 62.171 | J47: =[1]Ведомость!D84 -> 10470 | K47: =I47*J47*1.22 -> 794135.05 | O47: 4.365
A48: п | B48: info@imaengin.ru | C48: 8-911-956-34-71 | D48: Григорьева Марина | E48: =ROW()-11 -> 37 | F48: 92100-404Э от 01.04.2018 | G48: 7810445314 | H48: ИМА ИНЖИНИРИНГ ООО | I48: =[1]Итог!D78 -> 0.66 | J48: =[1]Ведомость!D85 -> 10470 | K48: =I48*J48*1.22 -> 8430.444 | O48: 10.919
...
